073D
BD0B
B899
Traceback (most recent call last):
  File "/home/aamer/python_projects/product_catalog/manage.py", line 22, in <module>
    main()
  File "/home/aamer/python_projects/product_catalog/manage.py", line 18, in main
    execute_from_command_line(sys.argv)
  File "/home/aamer/python_projects/yam/lib/python3.8/site-packages/django/core/management/__init__.py", line 425, in execute_from_command_line
    utility.execute()
  File "/home/aamer/python_projects/yam/lib/python3.8/site-packages/django/core/management/__init__.py", line 419, in execute
    self.fetch_command(subcommand).run_from_argv(self.argv)
  File "/home/aamer/python_projects/yam/lib/python3.8/site-packages/django/core/management/base.py", line 373, in run_from_argv
    self.execute(*args, **cmd_options)
  File "/home/aamer/python_projects/yam/lib/python3.8/site-packages/django/core/management/base.py", line 417, in execute
    output = self.handle(*args, **options)
  File "/home/aamer/python_projects/yam/lib/python3.8/site-packages/django_crontab/management/commands/crontab.py", line 29, in handle
    Crontab().run_job(options['jobhash'])
  File "/home/aamer/python_projects/yam/lib/python3.8/site-packages/django_crontab/crontab.py", line 126, in run_job
    job = self.__get_job_by_hash(job_hash)
  File "/home/aamer/python_projects/yam/lib/python3.8/site-packages/django_crontab/crontab.py", line 171, in __get_job_by_hash
    raise RuntimeError(
RuntimeError: No job with hash 9c51b87f143d6c7687dda626806ff5a3 found. It seems the crontab is out of sync with your settings.CRONJOBS. Run "python manage.py crontab add" again to resolve this issue!
Traceback (most recent call last):
  File "/home/aamer/python_projects/product_catalog/manage.py", line 22, in <module>
    main()
  File "/home/aamer/python_projects/product_catalog/manage.py", line 18, in main
    execute_from_command_line(sys.argv)
  File "/home/aamer/python_projects/yam/lib/python3.8/site-packages/django/core/management/__init__.py", line 425, in execute_from_command_line
    utility.execute()
  File "/home/aamer/python_projects/yam/lib/python3.8/site-packages/django/core/management/__init__.py", line 419, in execute
    self.fetch_command(subcommand).run_from_argv(self.argv)
  File "/home/aamer/python_projects/yam/lib/python3.8/site-packages/django/core/management/base.py", line 373, in run_from_argv
    self.execute(*args, **cmd_options)
  File "/home/aamer/python_projects/yam/lib/python3.8/site-packages/django/core/management/base.py", line 417, in execute
    output = self.handle(*args, **options)
  File "/home/aamer/python_projects/yam/lib/python3.8/site-packages/django_crontab/management/commands/crontab.py", line 29, in handle
    Crontab().run_job(options['jobhash'])
  File "/home/aamer/python_projects/yam/lib/python3.8/site-packages/django_crontab/crontab.py", line 126, in run_job
    job = self.__get_job_by_hash(job_hash)
  File "/home/aamer/python_projects/yam/lib/python3.8/site-packages/django_crontab/crontab.py", line 171, in __get_job_by_hash
    raise RuntimeError(
RuntimeError: No job with hash 9c51b87f143d6c7687dda626806ff5a3 found. It seems the crontab is out of sync with your settings.CRONJOBS. Run "python manage.py crontab add" again to resolve this issue!
Traceback (most recent call last):
  File "/home/aamer/python_projects/product_catalog/manage.py", line 22, in <module>
    main()
  File "/home/aamer/python_projects/product_catalog/manage.py", line 18, in main
    execute_from_command_line(sys.argv)
  File "/home/aamer/python_projects/yam/lib/python3.8/site-packages/django/core/management/__init__.py", line 425, in execute_from_command_line
    utility.execute()
  File "/home/aamer/python_projects/yam/lib/python3.8/site-packages/django/core/management/__init__.py", line 419, in execute
    self.fetch_command(subcommand).run_from_argv(self.argv)
  File "/home/aamer/python_projects/yam/lib/python3.8/site-packages/django/core/management/base.py", line 373, in run_from_argv
    self.execute(*args, **cmd_options)
  File "/home/aamer/python_projects/yam/lib/python3.8/site-packages/django/core/management/base.py", line 417, in execute
    output = self.handle(*args, **options)
  File "/home/aamer/python_projects/yam/lib/python3.8/site-packages/django_crontab/management/commands/crontab.py", line 29, in handle
    Crontab().run_job(options['jobhash'])
  File "/home/aamer/python_projects/yam/lib/python3.8/site-packages/django_crontab/crontab.py", line 126, in run_job
    job = self.__get_job_by_hash(job_hash)
  File "/home/aamer/python_projects/yam/lib/python3.8/site-packages/django_crontab/crontab.py", line 171, in __get_job_by_hash
    raise RuntimeError(
RuntimeError: No job with hash 9c51b87f143d6c7687dda626806ff5a3 found. It seems the crontab is out of sync with your settings.CRONJOBS. Run "python manage.py crontab add" again to resolve this issue!
Traceback (most recent call last):
  File "/home/aamer/python_projects/product_catalog/manage.py", line 22, in <module>
    main()
  File "/home/aamer/python_projects/product_catalog/manage.py", line 18, in main
    execute_from_command_line(sys.argv)
  File "/home/aamer/python_projects/yam/lib/python3.8/site-packages/django/core/management/__init__.py", line 425, in execute_from_command_line
    utility.execute()
  File "/home/aamer/python_projects/yam/lib/python3.8/site-packages/django/core/management/__init__.py", line 419, in execute
    self.fetch_command(subcommand).run_from_argv(self.argv)
  File "/home/aamer/python_projects/yam/lib/python3.8/site-packages/django/core/management/base.py", line 373, in run_from_argv
    self.execute(*args, **cmd_options)
  File "/home/aamer/python_projects/yam/lib/python3.8/site-packages/django/core/management/base.py", line 417, in execute
    output = self.handle(*args, **options)
  File "/home/aamer/python_projects/yam/lib/python3.8/site-packages/django_crontab/management/commands/crontab.py", line 29, in handle
    Crontab().run_job(options['jobhash'])
  File "/home/aamer/python_projects/yam/lib/python3.8/site-packages/django_crontab/crontab.py", line 126, in run_job
    job = self.__get_job_by_hash(job_hash)
  File "/home/aamer/python_projects/yam/lib/python3.8/site-packages/django_crontab/crontab.py", line 171, in __get_job_by_hash
    raise RuntimeError(
RuntimeError: No job with hash 9c51b87f143d6c7687dda626806ff5a3 found. It seems the crontab is out of sync with your settings.CRONJOBS. Run "python manage.py crontab add" again to resolve this issue!
Traceback (most recent call last):
  File "/home/aamer/python_projects/product_catalog/manage.py", line 22, in <module>
    main()
  File "/home/aamer/python_projects/product_catalog/manage.py", line 18, in main
    execute_from_command_line(sys.argv)
  File "/home/aamer/python_projects/yam/lib/python3.8/site-packages/django/core/management/__init__.py", line 425, in execute_from_command_line
    utility.execute()
  File "/home/aamer/python_projects/yam/lib/python3.8/site-packages/django/core/management/__init__.py", line 419, in execute
    self.fetch_command(subcommand).run_from_argv(self.argv)
  File "/home/aamer/python_projects/yam/lib/python3.8/site-packages/django/core/management/base.py", line 373, in run_from_argv
    self.execute(*args, **cmd_options)
  File "/home/aamer/python_projects/yam/lib/python3.8/site-packages/django/core/management/base.py", line 417, in execute
    output = self.handle(*args, **options)
  File "/home/aamer/python_projects/yam/lib/python3.8/site-packages/django_crontab/management/commands/crontab.py", line 29, in handle
    Crontab().run_job(options['jobhash'])
  File "/home/aamer/python_projects/yam/lib/python3.8/site-packages/django_crontab/crontab.py", line 126, in run_job
    job = self.__get_job_by_hash(job_hash)
  File "/home/aamer/python_projects/yam/lib/python3.8/site-packages/django_crontab/crontab.py", line 171, in __get_job_by_hash
    raise RuntimeError(
RuntimeError: No job with hash 9c51b87f143d6c7687dda626806ff5a3 found. It seems the crontab is out of sync with your settings.CRONJOBS. Run "python manage.py crontab add" again to resolve this issue!
Traceback (most recent call last):
  File "/home/aamer/python_projects/product_catalog/manage.py", line 22, in <module>
    main()
  File "/home/aamer/python_projects/product_catalog/manage.py", line 18, in main
    execute_from_command_line(sys.argv)
  File "/home/aamer/python_projects/yam/lib/python3.8/site-packages/django/core/management/__init__.py", line 425, in execute_from_command_line
    utility.execute()
  File "/home/aamer/python_projects/yam/lib/python3.8/site-packages/django/core/management/__init__.py", line 419, in execute
    self.fetch_command(subcommand).run_from_argv(self.argv)
  File "/home/aamer/python_projects/yam/lib/python3.8/site-packages/django/core/management/base.py", line 373, in run_from_argv
    self.execute(*args, **cmd_options)
  File "/home/aamer/python_projects/yam/lib/python3.8/site-packages/django/core/management/base.py", line 417, in execute
    output = self.handle(*args, **options)
  File "/home/aamer/python_projects/yam/lib/python3.8/site-packages/django_crontab/management/commands/crontab.py", line 29, in handle
    Crontab().run_job(options['jobhash'])
  File "/home/aamer/python_projects/yam/lib/python3.8/site-packages/django_crontab/crontab.py", line 126, in run_job
    job = self.__get_job_by_hash(job_hash)
  File "/home/aamer/python_projects/yam/lib/python3.8/site-packages/django_crontab/crontab.py", line 171, in __get_job_by_hash
    raise RuntimeError(
RuntimeError: No job with hash 9c51b87f143d6c7687dda626806ff5a3 found. It seems the crontab is out of sync with your settings.CRONJOBS. Run "python manage.py crontab add" again to resolve this issue!
Traceback (most recent call last):
  File "/home/aamer/python_projects/product_catalog/manage.py", line 22, in <module>
    main()
  File "/home/aamer/python_projects/product_catalog/manage.py", line 18, in main
    execute_from_command_line(sys.argv)
  File "/home/aamer/python_projects/yam/lib/python3.8/site-packages/django/core/management/__init__.py", line 425, in execute_from_command_line
    utility.execute()
  File "/home/aamer/python_projects/yam/lib/python3.8/site-packages/django/core/management/__init__.py", line 419, in execute
    self.fetch_command(subcommand).run_from_argv(self.argv)
  File "/home/aamer/python_projects/yam/lib/python3.8/site-packages/django/core/management/base.py", line 373, in run_from_argv
    self.execute(*args, **cmd_options)
  File "/home/aamer/python_projects/yam/lib/python3.8/site-packages/django/core/management/base.py", line 417, in execute
    output = self.handle(*args, **options)
  File "/home/aamer/python_projects/yam/lib/python3.8/site-packages/django_crontab/management/commands/crontab.py", line 29, in handle
    Crontab().run_job(options['jobhash'])
  File "/home/aamer/python_projects/yam/lib/python3.8/site-packages/django_crontab/crontab.py", line 126, in run_job
    job = self.__get_job_by_hash(job_hash)
  File "/home/aamer/python_projects/yam/lib/python3.8/site-packages/django_crontab/crontab.py", line 171, in __get_job_by_hash
    raise RuntimeError(
RuntimeError: No job with hash 9c51b87f143d6c7687dda626806ff5a3 found. It seems the crontab is out of sync with your settings.CRONJOBS. Run "python manage.py crontab add" again to resolve this issue!
Traceback (most recent call last):
  File "/home/aamer/python_projects/product_catalog/manage.py", line 22, in <module>
    main()
  File "/home/aamer/python_projects/product_catalog/manage.py", line 18, in main
    execute_from_command_line(sys.argv)
  File "/home/aamer/python_projects/yam/lib/python3.8/site-packages/django/core/management/__init__.py", line 425, in execute_from_command_line
    utility.execute()
  File "/home/aamer/python_projects/yam/lib/python3.8/site-packages/django/core/management/__init__.py", line 419, in execute
    self.fetch_command(subcommand).run_from_argv(self.argv)
  File "/home/aamer/python_projects/yam/lib/python3.8/site-packages/django/core/management/base.py", line 373, in run_from_argv
    self.execute(*args, **cmd_options)
  File "/home/aamer/python_projects/yam/lib/python3.8/site-packages/django/core/management/base.py", line 417, in execute
    output = self.handle(*args, **options)
  File "/home/aamer/python_projects/yam/lib/python3.8/site-packages/django_crontab/management/commands/crontab.py", line 29, in handle
    Crontab().run_job(options['jobhash'])
  File "/home/aamer/python_projects/yam/lib/python3.8/site-packages/django_crontab/crontab.py", line 126, in run_job
    job = self.__get_job_by_hash(job_hash)
  File "/home/aamer/python_projects/yam/lib/python3.8/site-packages/django_crontab/crontab.py", line 171, in __get_job_by_hash
    raise RuntimeError(
RuntimeError: No job with hash 9c51b87f143d6c7687dda626806ff5a3 found. It seems the crontab is out of sync with your settings.CRONJOBS. Run "python manage.py crontab add" again to resolve this issue!
Traceback (most recent call last):
  File "/home/aamer/python_projects/product_catalog/manage.py", line 22, in <module>
    main()
  File "/home/aamer/python_projects/product_catalog/manage.py", line 18, in main
    execute_from_command_line(sys.argv)
  File "/home/aamer/python_projects/yam/lib/python3.8/site-packages/django/core/management/__init__.py", line 425, in execute_from_command_line
    utility.execute()
  File "/home/aamer/python_projects/yam/lib/python3.8/site-packages/django/core/management/__init__.py", line 419, in execute
    self.fetch_command(subcommand).run_from_argv(self.argv)
  File "/home/aamer/python_projects/yam/lib/python3.8/site-packages/django/core/management/base.py", line 373, in run_from_argv
    self.execute(*args, **cmd_options)
  File "/home/aamer/python_projects/yam/lib/python3.8/site-packages/django/core/management/base.py", line 417, in execute
    output = self.handle(*args, **options)
  File "/home/aamer/python_projects/yam/lib/python3.8/site-packages/django_crontab/management/commands/crontab.py", line 29, in handle
    Crontab().run_job(options['jobhash'])
  File "/home/aamer/python_projects/yam/lib/python3.8/site-packages/django_crontab/crontab.py", line 126, in run_job
    job = self.__get_job_by_hash(job_hash)
  File "/home/aamer/python_projects/yam/lib/python3.8/site-packages/django_crontab/crontab.py", line 171, in __get_job_by_hash
    raise RuntimeError(
RuntimeError: No job with hash 9c51b87f143d6c7687dda626806ff5a3 found. It seems the crontab is out of sync with your settings.CRONJOBS. Run "python manage.py crontab add" again to resolve this issue!
Traceback (most recent call last):
  File "/home/aamer/python_projects/product_catalog/manage.py", line 22, in <module>
    main()
  File "/home/aamer/python_projects/product_catalog/manage.py", line 18, in main
    execute_from_command_line(sys.argv)
  File "/home/aamer/python_projects/yam/lib/python3.8/site-packages/django/core/management/__init__.py", line 425, in execute_from_command_line
    utility.execute()
  File "/home/aamer/python_projects/yam/lib/python3.8/site-packages/django/core/management/__init__.py", line 419, in execute
    self.fetch_command(subcommand).run_from_argv(self.argv)
  File "/home/aamer/python_projects/yam/lib/python3.8/site-packages/django/core/management/base.py", line 373, in run_from_argv
    self.execute(*args, **cmd_options)
  File "/home/aamer/python_projects/yam/lib/python3.8/site-packages/django/core/management/base.py", line 417, in execute
    output = self.handle(*args, **options)
  File "/home/aamer/python_projects/yam/lib/python3.8/site-packages/django_crontab/management/commands/crontab.py", line 29, in handle
    Crontab().run_job(options['jobhash'])
  File "/home/aamer/python_projects/yam/lib/python3.8/site-packages/django_crontab/crontab.py", line 126, in run_job
    job = self.__get_job_by_hash(job_hash)
  File "/home/aamer/python_projects/yam/lib/python3.8/site-packages/django_crontab/crontab.py", line 171, in __get_job_by_hash
    raise RuntimeError(
RuntimeError: No job with hash 9c51b87f143d6c7687dda626806ff5a3 found. It seems the crontab is out of sync with your settings.CRONJOBS. Run "python manage.py crontab add" again to resolve this issue!
Traceback (most recent call last):
  File "/home/aamer/python_projects/product_catalog/manage.py", line 22, in <module>
    main()
  File "/home/aamer/python_projects/product_catalog/manage.py", line 18, in main
    execute_from_command_line(sys.argv)
  File "/home/aamer/python_projects/yam/lib/python3.8/site-packages/django/core/management/__init__.py", line 425, in execute_from_command_line
    utility.execute()
  File "/home/aamer/python_projects/yam/lib/python3.8/site-packages/django/core/management/__init__.py", line 419, in execute
    self.fetch_command(subcommand).run_from_argv(self.argv)
  File "/home/aamer/python_projects/yam/lib/python3.8/site-packages/django/core/management/base.py", line 373, in run_from_argv
    self.execute(*args, **cmd_options)
  File "/home/aamer/python_projects/yam/lib/python3.8/site-packages/django/core/management/base.py", line 417, in execute
    output = self.handle(*args, **options)
  File "/home/aamer/python_projects/yam/lib/python3.8/site-packages/django_crontab/management/commands/crontab.py", line 29, in handle
    Crontab().run_job(options['jobhash'])
  File "/home/aamer/python_projects/yam/lib/python3.8/site-packages/django_crontab/crontab.py", line 126, in run_job
    job = self.__get_job_by_hash(job_hash)
  File "/home/aamer/python_projects/yam/lib/python3.8/site-packages/django_crontab/crontab.py", line 171, in __get_job_by_hash
    raise RuntimeError(
RuntimeError: No job with hash 9c51b87f143d6c7687dda626806ff5a3 found. It seems the crontab is out of sync with your settings.CRONJOBS. Run "python manage.py crontab add" again to resolve this issue!
